<?xml version="1.0" encoding="utf-8"?>

<robot
  name="gate_system">
  <link name="world"/>
  <link
    name="base_link">
    <inertial>
      <origin
        xyz="1.0311 -2.5557 2.3905"
        rpy="0 0 0" />
      <mass
        value="1100.87" />
      <inertia
        ixx="0.037259"
        ixy="2.1212E-19"
        ixz="8.3317E-20"
        iyy="0.0024207"
        iyz="-0.0078999"
        izz="0.035026" />
    </inertial>
    <visual>
      <origin
        xyz="0 0 0"
        rpy="0 0 0" />
      <geometry>
        <mesh
          filename="package://gate_system/meshes/base_link.STL" />
      </geometry>
      <material
        name="red">
        <color
          rgba="0.75 0.0 0.0 1" />
      </material>
    </visual>
    <collision>
      <origin
        xyz="0 0 0"
        rpy="0 0 0" />
      <geometry>
        <mesh
          filename="package://gate_system/meshes/base_link.STL" />
      </geometry>
    </collision>
  </link>
  <link
    name="rotating_link">
    <inertial>
      <origin
        xyz="0 0.27188 0.062404"
        rpy="0 0 0" />
      <mass
        value="0.1" />
      <inertia
        ixx="0.037259"
        ixy="2.1212E-19"
        ixz="8.3317E-20"
        iyy="0.0024207"
        iyz="-0.0078999"
        izz="0.035026" />
    </inertial>
    <visual>
      <origin
        xyz="0 0 0"
        rpy="0 0 0" />
      <geometry>
        <mesh
          filename="package://gate_system/meshes/rotating_link.STL" />
      </geometry>
      <material name="red">
        <color
          rgba="1 0 0 1" />
      </material>
    </visual>
    <collision>
      <origin
        xyz="0 0 0"
        rpy="0 0 0" />
      <geometry>
        <mesh
          filename="package://gate_system/meshes/rotating_link.STL" />
      </geometry>
    </collision>
  </link>
  <joint
    name="rotating_joint"
    type="continuous">
    <origin
      xyz="1.0311 -2.4707 2.523"
      rpy="1.5708 0 1.5708" />
    <parent
      link="base_link" />
    <child
      link="rotating_link" />
    <axis
      xyz="-1 0 0" />
    <limit
      effort="0"
      velocity="0" />
  </joint>


  <joint name="fixed" type="fixed">
    <parent link="world"/>
    <child link="base_link"/>
    <origin xyz="0 0 0" rpy="0 0 0"/>
  </joint>

  <gazebo reference="base_link" type="fixed">
    <material>Gazebo/White</material>
    <mu1>500</mu1>
    <mu2>500</mu2>
    <selfCollide>False</selfCollide>
    <static>true</static>
  </gazebo>
  
  <gazebo reference="rotating_link">
    <material>Gazebo/Orange</material>
    <mu1>0.2</mu1>
    <mu2>0.2</mu2>
    <gravity>false</gravity>
    <selfCollide>false</selfCollide>
    <static>false</static>
  </gazebo>

</robot>
